Workbook

Sheet Combined Portfolio Performance
A1: Sr. No. | C1: Sector | D1: COMPANY NAME | E1: Quaterly Price | M1: Profit Amount for Equal Disttribution | W1: Profit Amount for Maximum Porfolio Retuns | AG1: Profit Amount for Max Sharpe Ratio
B2: Symbol | E2: As on 01-04-24 | F2: As on 30-06-24 | G2: As on 30-09-24 | H2: As on 31-12-24 | I2: As on 31-03-25 | J2: As on 30-06-25 | K2: As on 30-09-25 | M2: Weights (6.67%) | N2: No. Shares | O2: As on 01-04-24 | P2: As on 30-06-24 | Q2: As on 30-09-24 | R2: As on 31-12-24 | S2: As on 31-03-25 | T2: As on 30-06-25 | U2: As on 30-09-25 | W2: Max -Profit Weight | X2: No. Shares | Y2: As on 01-04-24 | Z2: As on 30-06-24 | AA2: As on 30-09-24 | AB2: As on 31-12-24 | AC2: As on 31-03-25 | AD2: As on 30-06-25 | AE2: As on 30-09-25 | AG2: Max -Sharpe Ratio Weight | AH2: No. Shares | AI2: As on 01-04-24 | AJ2: As on 30-06-24 | AK2: As on 30-09-24 | AL2: As on 31-12-24 | AM2: As on 31-03-25 | AN2: As on 30-06-25 | AO2: As on 30-09-25
A3: 1 | B3: TATACOMM | C3: TELECOM | D3: Tata Communications Ltd | E3: 2036.6 | F3: 1854.5 | G3: 2134.8 | H3: 1703.4 | I3: 1578.2 | J3: 1690.6 | K3: 1613 | M3: =1/15 -> 0.066666667 | N3: =ROUND(800000*M3/E3,0) -> 26 | O3: =N3*E3 -> 52951.6 | P3: =$N3*(F3-$E3) -> -4734.6 | Q3: =$N3*(G3-$E3) -> 2553.2 | R3: =$N3*(H3-$E3) -> -8663.2 | S3: =$N3*(I3-$E3) -> -11918.4 | T3: =$N3*(J3-$E3) -> -8996 | U3: =$N3*(K3-$E3) -> -11013.6 | W3: 0.18000001 | X3: =ROUND(800000*W3/E3,0) -> 71 | Y3: =X3*$E3 -> 144598.6 | Z3: =$X3*(F3-$E3) -> -12929.1 | AA3: =$X3*(G3-$E3) -> 6972.2 | AB3: =$X3*(H3-$E3) -> -23657.2 | AC3: =$X3*(I3-$E3) -> -32546.4 | AD3: =$X3*(J3-$E3) -> -24566 | AE3: =$X3*(K3-$E3) -> -30075.6 | AG3: 0.02 | AH3: =ROUND(800000*AG3/I3,0) -> 10 | AI3: =AH3*$E3 -> 20366 | AJ3: =$AH3*(F3-$E3) -> -1821 | AK3: =$AH3*(G3-$E3) -> 982 | AL3: =$AH3*(H3-$E3) -> -3332 | AM3: =$AH3*(I3-$E3) -> -4584 | AN3: =$AH3*(J3-$E3) -> -3460 | AO3: =$AH3*(K3-$E3) -> -4236
A4: 2 | B4: NELCO | C4: TELECOM | D4: Nelco Ltd | E4: 718.4 | F4: 770.3 | G4: 1028 | H4: 1262.3 | I4: 896.3 | J4: 1010.9 | K4: 842.2 | M4: =1/15 -> 0.066666667 | N4: =ROUND(800000*M4/E4,0) -> 74 | O4: =N4*E4 -> 53161.6 | P4: =$N4*(F4-$E4) -> 3840.6 | Q4: =$N4*(G4-$E4) -> 22910.4 | R4: =$N4*(H4-$E4) -> 40248.6 | S4: =$N4*(I4-$E4) -> 13164.6 | T4: =$N4*(J4-$E4) -> 21645 | U4: =$N4*(K4-$E4) -> 9161.2 | W4: 0.02 | X4: =ROUND(800000*W4/E4,0) -> 22 | Y4: =X4*$E4 -> 15804.8 | Z4: =$X4*(F4-$E4) -> 1141.8 | AA4: =$X4*(G4-$E4) -> 6811.2 | AB4: =$X4*(H4-$E4) -> 11965.8 | AC4: =$X4*(I4-$E4) -> 3913.8 | AD4: =$X4*(J4-$E4) -> 6435 | AE4: =$X4*(K4-$E4) -> 2723.6 | AG4: 0.2 | AH4: =ROUND(800000*AG4/I4,0) -> 179 | AI4: =AH4*$E4 -> 128593.6 | AJ4: =$AH4*(F4-$E4) -> 9290.1 | AK4: =$AH4*(G4-$E4) -> 55418.4 | AL4: =$AH4*(H4-$E4) -> 97358.1 | AM4: =$AH4*(I4-$E4) -> 31844.1 | AN4: =$AH4*(J4-$E4) -> 52357.5 | AO4: =$AH4*(K4-$E4) -> 22160.2
A5: 3 | B5: INDUSTOWER | C5: TELECOM | D5: Indus Towers Ltd | E5: 315.2 | F5: 375.3 | G5: 392.6 | H5: 341.8 | I5: 352.5 | J5: 421.1 | K5: 342.9 | M5: =1/15 -> 0.066666667 | N5: =ROUND(800000*M5/E5,0) -> 169 | O5: =N5*E5 -> 53268.8 | P5: =$N5*(F5-$E5) -> 10156.9 | Q5: =$N5*(G5-$E5) -> 13080.6 | R5: =$N5*(H5-$E5) -> 4495.4 | S5: =$N5*(I5-$E5) -> 6303.7 | T5: =$N5*(J5-$E5) -> 17897.1 | U5: =$N5*(K5-$E5) -> 4681.3 | W5: 0.02 | X5: =ROUND(800000*W5/E5,0) -> 51 | Y5: =X5*$E5 -> 16075.2 | Z5: =$X5*(F5-$E5) -> 3065.1 | AA5: =$X5*(G5-$E5) -> 3947.4 | AB5: =$X5*(H5-$E5) -> 1356.6 | AC5: =$X5*(I5-$E5) -> 1902.3 | AD5: =$X5*(J5-$E5) -> 5400.9 | AE5: =$X5*(K5-$E5) -> 1412.7 | AG5: 0.2 | AH5: =ROUND(800000*AG5/I5,0) -> 454 | AI5: =AH5*$E5 -> 143100.8 | AJ5: =$AH5*(F5-$E5) -> 27285.4 | AK5: =$AH5*(G5-$E5) -> 35139.6 | AL5: =$AH5*(H5-$E5) -> 12076.4 | AM5: =$AH5*(I5-$E5) -> 16934.2 | AN5: =$AH5*(J5-$E5) -> 48078.6 | AO5: =$AH5*(K5-$E5) -> 12575.8
A6: 4 | B6: ANTELOPUS | C6: Oil and gas | D6: Antelopus | E6: 459.9 | F6: 731.8 | G6: 845.6 | H6: 819.9 | I6: 573.4 | J6: 694.9 | K6: 551.8 | M6: =1/15 -> 0.066666667 | N6: =ROUND(800000*M6/E6,0) -> 116 | O6: =N6*E6 -> 53348.4 | P6: =$N6*(F6-$E6) -> 31540.4 | Q6: =$N6*(G6-$E6) -> 44741.2 | R6: =$N6*(H6-$E6) -> 41760 | S6: =$N6*(I6-$E6) -> 13166 | T6: =$N6*(J6-$E6) -> 27260 | U6: =$N6*(K6-$E6) -> 10660.4 | W6: 0.02 | X6: =ROUND(800000*W6/E6,0) -> 35 | Y6: =X6*$E6 -> 16096.5 | Z6: =$X6*(F6-$E6) -> 9516.5 | AA6: =$X6*(G6-$E6) -> 13499.5 | AB6: =$X6*(H6-$E6) -> 12600 | AC6: =$X6*(I6-$E6) -> 3972.5 | AD6: =$X6*(J6-$E6) -> 8225 | AE6: =$X6*(K6-$E6) -> 3216.5 | AG6: 0.2 | AH6: =ROUND(800000*AG6/I6,0) -> 279 | AI6: =AH6*$E6 -> 128312.1 | AJ6: =$AH6*(F6-$E6) -> 75860.1 | AK6: =$AH6*(G6-$E6) -> 107610.3 | AL6: =$AH6*(H6-$E6) -> 100440 | AM6: =$AH6*(I6-$E6) -> 31666.5 | AN6: =$AH6*(J6-$E6) -> 65565 | AO6: =$AH6*(K6-$E6) -> 25640.1
A7: 5 | B7: ONGC | C7: Oil and gas | D7: Oil and Natural Gas Corporation Ltd | E7: 269.9 | F7: 274.2 | G7: 297.6 | H7: 239.3 | I7: 248.1 | J7: 244.2 | K7: 239.5 | M7: =1/15 -> 0.066666667 | N7: =ROUND(800000*M7/E7,0) -> 198 | O7: =N7*E7 -> 53440.2 | P7: =$N7*(F7-$E7) -> 851.4 | Q7: =$N7*(G7-$E7) -> 5484.6 | R7: =$N7*(H7-$E7) -> -6058.8 | S7: =$N7*(I7-$E7) -> -4316.4 | T7: =$N7*(J7-$E7) -> -5088.6 | U7: =$N7*(K7-$E7) -> -6019.2 | W7: 0.02 | X7: =ROUND(800000*W7/E7,0) -> 59 | Y7: =X7*$E7 -> 15924.1 | Z7: =$X7*(F7-$E7) -> 253.7 | AA7: =$X7*(G7-$E7) -> 1634.3 | AB7: =$X7*(H7-$E7) -> -1805.4 | AC7: =$X7*(I7-$E7) -> -1286.2 | AD7: =$X7*(J7-$E7) -> -1516.3 | AE7: =$X7*(K7-$E7) -> -1793.6 | AG7: 0.02 | AH7: =ROUND(800000*AG7/I7,0) -> 64 | AI7: =AH7*$E7 -> 17273.6 | AJ7: =$AH7*(F7-$E7) -> 275.2 | AK7: =$AH7*(G7-$E7) -> 1772.8 | AL7: =$AH7*(H7-$E7) -> -1958.4 | AM7: =$AH7*(I7-$E7) -> -1395.2 | AN7: =$AH7*(J7-$E7) -> -1644.8 | AO7: =$AH7*(K7-$E7) -> -1945.6
A8: 6 | B8: HINDOILEXP | C8: Oil and gas | D8: Hindustan Oil Exploration Company Ltd | E8: 181.6 | F8: 196 | G8: 231.1 | H8: 183.2 | I8: 172.6 | J8: 167.1 | K8: 170.3 | M8: =1/15 -> 0.066666667 | N8: =ROUND(800000*M8/E8,0) -> 294 | O8: =N8*E8 -> 53390.4 | P8: =$N8*(F8-$E8) -> 4233.6 | Q8: =$N8*(G8-$E8) -> 14553 | R8: =$N8*(H8-$E8) -> 470.4 | S8: =$N8*(I8-$E8) -> -2646 | T8: =$N8*(J8-$E8) -> -4263 | U8: =$N8*(K8-$E8) -> -3322.2 | W8: 0.02 | X8: =ROUND(800000*W8/E8,0) -> 88 | Y8: =X8*$E8 -> 15980.8 | Z8: =$X8*(F8-$E8) -> 1267.2 | AA8: =$X8*(G8-$E8) -> 4356 | AB8: =$X8*(H8-$E8) -> 140.8 | AC8: =$X8*(I8-$E8) -> -792 | AD8: =$X8*(J8-$E8) -> -1276 | AE8: =$X8*(K8-$E8) -> -994.4 | AG8: 0.02 | AH8: =ROUND(800000*AG8/I8,0) -> 93 | AI8: =AH8*$E8 -> 16888.8 | AJ8: =$AH8*(F8-$E8) -> 1339.2 | AK8: =$AH8*(G8-$E8) -> 4603.5 | AL8: =$AH8*(H8-$E8) -> 148.8 | AM8: =$AH8*(I8-$E8) -> -837 | AN8: =$AH8*(J8-$E8) -> -1348.5 | AO8: =$AH8*(K8-$E8) -> -1050.9
A9: 7 | B9: TTKPRESTIG | C9: Consumer Electronics | D9: TTK Prestige Ltd | E9: 692.5 | F9: 786.8 | G9: 875.4 | H9: 809.9 | I9: 612.7 | J9: 624.4 | K9: 635.2 | M9: =1/15 -> 0.066666667 | N9: =ROUND(800000*M9/E9,0) -> 77 | O9: =N9*E9 -> 53322.5 | P9: =$N9*(F9-$E9) -> 7261.1 | Q9: =$N9*(G9-$E9) -> 14083.3 | R9: =$N9*(H9-$E9) -> 9039.8 | S9: =$N9*(I9-$E9) -> -6144.6 | T9: =$N9*(J9-$E9) -> -5243.7 | U9: =$N9*(K9-$E9) -> -4412.1 | W9: 0.02 | X9: =ROUND(800000*W9/E9,0) -> 23 | Y9: =X9*$E9 -> 15927.5 | Z9: =$X9*(F9-$E9) -> 2168.9 | AA9: =$X9*(G9-$E9) -> 4206.7 | AB9: =$X9*(H9-$E9) -> 2700.2 | AC9: =$X9*(I9-$E9) -> -1835.4 | AD9: =$X9*(J9-$E9) -> -1566.3 | AE9: =$X9*(K9-$E9) -> -1317.9 | AG9: 0.02 | AH9: =ROUND(800000*AG9/I9,0) -> 26 | AI9: =AH9*$E9 -> 18005 | AJ9: =$AH9*(F9-$E9) -> 2451.8 | AK9: =$AH9*(G9-$E9) -> 4755.4 | AL9: =$AH9*(H9-$E9) -> 3052.4 | AM9: =$AH9*(I9-$E9) -> -2074.8 | AN9: =$AH9*(J9-$E9) -> -1770.6 | AO9: =$AH9*(K9-$E9) -> -1489.8
A10: 8 | B10: VOLTAS | C10: Consumer Electronics | D10: Voltas Ltd | E10: 1151.6 | F10: 1472.2 | G10: 1845.1 | H10: 1790 | I10: 1352.1 | J10: 1314.1 | K10: 1354 | M10: =1/15 -> 0.066666667 | N10: =ROUND(800000*M10/E10,0) -> 46 | O10: =N10*E10 -> 52973.6 | P10: =$N10*(F10-$E10) -> 14747.6 | Q10: =$N10*(G10-$E10) -> 31901 | R10: =$N10*(H10-$E10) -> 29366.4 | S10: =$N10*(I10-$E10) -> 9223 | T10: =$N10*(J10-$E10) -> 7475 | U10: =$N10*(K10-$E10) -> 9310.4 | W10: 0.02 | X10: =ROUND(800000*W10/E10,0) -> 14 | Y10: =X10*$E10 -> 16122.4 | Z10: =$X10*(F10-$E10) -> 4488.4 | AA10: =$X10*(G10-$E10) -> 9709 | AB10: =$X10*(H10-$E10) -> 8937.6 | AC10: =$X10*(I10-$E10) -> 2807 | AD10: =$X10*(J10-$E10) -> 2275 | AE10: =$X10*(K10-$E10) -> 2833.6 | AG10: 0.02 | AH10: =ROUND(800000*AG10/I10,0) -> 12 | AI10: =AH10*$E10 -> 13819.2 | AJ10: =$AH10*(F10-$E10) -> 3847.2 | AK10: =$AH10*(G10-$E10) -> 8322 | AL10: =$AH10*(H10-$E10) -> 7660.8 | AM10: =$AH10*(I10-$E10) -> 2406 | AN10: =$AH10*(J10-$E10) -> 1950 | AO10: =$AH10*(K10-$E10) -> 2428.8
A11: 9 | B11: WHR | C11: Consumer Electronics | D11: Whirlpool of India Ltd | E11: 119.2 | F11: 87.03 | G11: 102.7 | H11: 114.5 | I11: 91.2 | J11: 93 | K11: 81.09 | M11: =1/15 -> 0.066666667 | N11: =ROUND(800000*M11/E11,0) -> 447 | O11: =N11*E11 -> 53282.4 | P11: =$N11*(F11-$E11) -> -14379.99 | Q11: =$N11*(G11-$E11) -> -7375.5 | R11: =$N11*(H11-$E11) -> -2100.9 | S11: =$N11*(I11-$E11) -> -12516 | T11: =$N11*(J11-$E11) -> -11711.4 | U11: =$N11*(K11-$E11) -> -17035.17 | W11: 0.02 | X11: =ROUND(800000*W11/E11,0) -> 134 | Y11: =X11*$E11 -> 15972.8 | Z11: =$X11*(F11-$E11) -> -4310.78 | AA11: =$X11*(G11-$E11) -> -2211 | AB11: =$X11*(H11-$E11) -> -629.8 | AC11: =$X11*(I11-$E11) -> -3752 | AD11: =$X11*(J11-$E11) -> -3510.8 | AE11: =$X11*(K11-$E11) -> -5106.74 | AG11: 0.02 | AH11: =ROUND(800000*AG11/I11,0) -> 175 | AI11: =AH11*$E11 -> 20860 | AJ11: =$AH11*(F11-$E11) -> -5629.75 | AK11: =$AH11*(G11-$E11) -> -2887.5 | AL11: =$AH11*(H11-$E11) -> -822.5 | AM11: =$AH11*(I11-$E11) -> -4900 | AN11: =$AH11*(J11-$E11) -> -4585 | AO11: =$AH11*(K11-$E11) -> -6669.25
A12: 10 | B12: MAITHANALL | C12: Metal | D12: Maithan Alloys Ltd | E12: 1021.3 | F12: 1190.3 | G12: 1158.1 | H12: 1119.2 | I12: 909.15 | J12: 1232.4 | K12: 1099 | M12: =1/15 -> 0.066666667 | N12: =ROUND(800000*M12/E12,0) -> 52 | O12: =N12*E12 -> 53107.6 | P12: =$N12*(F12-$E12) -> 8788 | Q12: =$N12*(G12-$E12) -> 7113.6 | R12: =$N12*(H12-$E12) -> 5090.8 | S12: =$N12*(I12-$E12) -> -5831.8 | T12: =$N12*(J12-$E12) -> 10977.2 | U12: =$N12*(K12-$E12) -> 4040.4 | W12: 0.02 | X12: =ROUND(800000*W12/E12,0) -> 16 | Y12: =X12*$E12 -> 16340.8 | Z12: =$X12*(F12-$E12) -> 2704 | AA12: =$X12*(G12-$E12) -> 2188.8 | AB12: =$X12*(H12-$E12) -> 1566.4 | AC12: =$X12*(I12-$E12) -> -1794.4 | AD12: =$X12*(J12-$E12) -> 3377.6 | AE12: =$X12*(K12-$E12) -> 1243.2 | AG12: 0.02 | AH12: =ROUND(800000*AG12/I12,0) -> 18 | AI12: =AH12*$E12 -> 18383.4 | AJ12: =$AH12*(F12-$E12) -> 3042 | AK12: =$AH12*(G12-$E12) -> 2462.4 | AL12: =$AH12*(H12-$E12) -> 1762.2 | AM12: =$AH12*(I12-$E12) -> -2018.7 | AN12: =$AH12*(J12-$E12) -> 3799.8 | AO12: =$AH12*(K12-$E12) -> 1398.6
A13: 11 | B13: SARDAEN | C13: Metal | D13: Sarda Energy & Minerals Ltd | E13: 207.1 | F13: 232.6 | G13: 443 | H13: 482.7 | I13: 528.1 | J13: 443.4 | K13: 539.4 | M13: =1/15 -> 0.066666667 | N13: =ROUND(800000*M13/E13,0) -> 258 | O13: =N13*E13 -> 53431.8 | P13: =$N13*(F13-$E13) -> 6579 | Q13: =$N13*(G13-$E13) -> 60862.2 | R13: =$N13*(H13-$E13) -> 71104.8 | S13: =$N13*(I13-$E13) -> 82818 | T13: =$N13*(J13-$E13) -> 60965.4 | U13: =$N13*(K13-$E13) -> 85733.4 | W13: 0.2 | X13: =ROUND(800000*W13/E13,0) -> 773 | Y13: =X13*$E13 -> 160088.3 | Z13: =$X13*(F13-$E13) -> 19711.5 | AA13: =$X13*(G13-$E13) -> 182350.7 | AB13: =$X13*(H13-$E13) -> 213038.8 | AC13: =$X13*(I13-$E13) -> 248133 | AD13: =$X13*(J13-$E13) -> 182659.9 | AE13: =$X13*(K13-$E13) -> 256867.9 | AG13: 0.02 | AH13: =ROUND(800000*AG13/I13,0) -> 30 | AI13: =AH13*$E13 -> 6213 | AJ13: =$AH13*(F13-$E13) -> 765 | AK13: =$AH13*(G13-$E13) -> 7077 | AL13: =$AH13*(H13-$E13) -> 8268 | AM13: =$AH13*(I13-$E13) -> 9630 | AN13: =$AH13*(J13-$E13) -> 7089 | AO13: =$AH13*(K13-$E13) -> 9969
A14: 12 | B14: TATASTEEL | C14: Metal | D14: Tata Steel Ltd | E14: 163.2 | F14: 174 | G14: 168.6 | H14: 138.1 | I14: 153.1 | J14: 159.8 | K14: 168.8 | M14: =1/15 -> 0.066666667 | N14: =ROUND(800000*M14/E14,0) -> 327 | O14: =N14*E14 -> 53366.4 | P14: =$N14*(F14-$E14) -> 3531.6 | Q14: =$N14*(G14-$E14) -> 1765.8 | R14: =$N14*(H14-$E14) -> -8207.7 | S14: =$N14*(I14-$E14) -> -3302.7 | T14: =$N14*(J14-$E14) -> -1111.8 | U14: =$N14*(K14-$E14) -> 1831.2 | W14: 0.02 | X14: =ROUND(800000*W14/E14,0) -> 98 | Y14: =X14*$E14 -> 15993.6 | Z14: =$X14*(F14-$E14) -> 1058.4 | AA14: =$X14*(G14-$E14) -> 529.2 | AB14: =$X14*(H14-$E14) -> -2459.8 | AC14: =$X14*(I14-$E14) -> -989.8 | AD14: =$X14*(J14-$E14) -> -333.2 | AE14: =$X14*(K14-$E14) -> 548.8 | AG14: 0.02 | AH14: =ROUND(800000*AG14/I14,0) -> 105 | AI14: =AH14*$E14 -> 17136 | AJ14: =$AH14*(F14-$E14) -> 1134 | AK14: =$AH14*(G14-$E14) -> 567 | AL14: =$AH14*(H14-$E14) -> -2635.5 | AM14: =$AH14*(I14-$E14) -> -1060.5 | AN14: =$AH14*(J14-$E14) -> -357 | AO14: =$AH14*(K14-$E14) -> 588
... A17: 15 | B17: JINDRILL | C17: Construction | D17: Jindal Drilling & Industries Ltd | E17: 634.4 | F17: 635.8 | G17: 616.8 | H17: 771 | I17: 876.7 | J17: 286.05604 | K17: 594.4 | M17: =1/15 -> 0.066666667 | N17: =ROUND(800000*M17/E17,0) -> 84 | O17: =N17*E17 -> 53289.6 | P17: =$N17*(F17-$E17) -> 117.6 | Q17: =$N17*(G17-$E17) -> -1478.4 | R17: =$N17*(H17-$E17) -> 11474.4 | S17: =$N17*(I17-$E17) -> 20353.2 | T17: =$N17*(J17-$E17) -> -29260.892 | U17: =$N17*(K17-$E17) -> -3360 | W17: 0.2 | X17: =ROUND(800000*W17/E17,0) -> 252 | Y17: =X17*$E17 -> 159868.8 | Z17: =$X17*(F17-$E17) -> 352.8 | AA17: =$X17*(G17-$E17) -> -4435.2 | AB17: =$X17*(H17-$E17) -> 34423.2 | AC17: =$X17*(I17-$E17) -> 61059.6 | AD17: =$X17*(J17-$E17) -> -87782.677 | AE17: =$X17*(K17-$E17) -> -10080 | AG17: 0.18 | AH17: =ROUND(800000*AG17/I17,0) -> 164 | AI17: =AH17*$E17 -> 104041.6 | AJ17: =$AH17*(F17-$E17) -> 229.6 | AK17: =$AH17*(G17-$E17) -> -2886.4 | AL17: =$AH17*(H17-$E17) -> 22402.4 | AM17: =$AH17*(I17-$E17) -> 39737.2 | AN17: =$AH17*(J17-$E17) -> -57128.409 | AO17: =$AH17*(K17-$E17) -> -6560
A18: Total | M18: =SUM(M3:M17) -> 1 | N18: =SUM(N3:N17) -> 2531 | O18: =SUM(O3:O17) -> 799158.9 | P18: =SUM(P3:P17) -> 125869.61 | Q18: =SUM(Q3:Q17) -> 293506.8 | R18: =SUM(R3:R17) -> 255416.8 | S18: =SUM(S3:S17) -> 147580.2 | T18: =SUM(T3:T17) -> 130233.77 | U18: =SUM(U3:U17) -> 127755.33 | W18: =SUM(W3:W17) -> 1 | X18: =SUM(X3:X17) -> 2206 | Y18: =SUM(Y3:Y17) -> 800724.7 | Z18: =SUM(Z3:Z17) -> 107741.22 | AA18: =SUM(AA3:AA17) -> 367909.2 | AB18: =SUM(AB3:AB17) -> 417965.3 | AC18: =SUM(AC3:AC17) -> 380491.4 | AD18: =SUM(AD3:AD17) -> 208425.35 | AE18: =SUM(AE3:AE17) -> 320248.36 | AG18: =SUM(AG3:AG17) -> 1 | AH18: =SUM(AH3:AH17) -> 1685 | AI18: =SUM(AI3:AI17) -> 675231.1 | AJ18: =SUM(AJ3:AJ17) -> 129305.65 | AK18: =SUM(AK3:AK17) -> 240262.1 | AL18: =SUM(AL3:AL17) -> 257692.3 | AM18: =SUM(AM3:AM17) -> 125275 | AN18: =SUM(AN3:AN17) -> 118286.82 | AO18: =SUM(AO3:AO17) -> 62346.55

Sheet Sector wise Performance
A1: Sr. No. | C1: Sector | D1: COMPANY NAME | E1: Quaterly Price | M1: Profit Amount for Equal Disttribution | W1: Profit Amount for Maximum Porfolio Retuns | AG1: Profit Amount for Max Sharpe Ratio
B2: Symbol | E2: As on 01-04-24 | F2: As on 30-06-24 | G2: As on 30-09-24 | H2: As on 31-12-24 | I2: As on 31-03-25 | J2: As on 30-06-25 | K2: As on 30-09-25 | M2: Weights (33.33%) | N2: No. Shares | O2: As on 01-04-24 | P2: As on 30-06-24 | Q2: As on 30-09-24 | R2: As on 31-12-24 | S2: As on 31-03-25 | T2: As on 30-06-25 | U2: As on 30-09-25 | W2: Max -Profit Weight | X2: No. Shares | Y2: As on 01-04-24 | Z2: As on 30-06-24 | AA2: As on 30-09-24 | AB2: As on 31-12-24 | AC2: As on 31-03-25 | AD2: As on 30-06-25 | AE2: As on 30-09-25 | AG2: Max -Sharpe Ratio Weight | AH2: No. Shares | AI2: As on 01-04-24 | AJ2: As on 30-06-24 | AK2: As on 30-09-24 | AL2: As on 31-12-24 | AM2: As on 31-03-25 | AN2: As on 30-06-25 | AO2: As on 30-09-25
A3: 1 | B3: TATACOMM | C3: TELECOM | D3: Tata Communications Ltd | E3: 2036.6 | F3: 1854.5 | G3: 2134.8 | H3: 1703.4 | I3: 1578.2 | J3: 1690.6 | K3: 1613 | M3: =1/3 -> 0.33333333 | N3: =ROUND(160000*M3/E3,0) -> 26 | O3: =N3*E3 -> 52951.6 | P3: =$N3*(F3-$E3) -> -4734.6 | Q3: =$N3*(G3-$E3) -> 2553.2 | R3: =$N3*(H3-$E3) -> -8663.2 | S3: =$N3*(I3-$E3) -> -11918.4 | T3: =$N3*(J3-$E3) -> -8996 | U3: =$N3*(K3-$E3) -> -11013.6 | W3: 0.4 | X3: =ROUND(160000*W3/E3,0) -> 31 | Y3: =X3*$E3 -> 63134.6 | Z3: =$X3*(F3-$E3) -> -5645.1 | AA3: =$X3*(G3-$E3) -> 3044.2 | AB3: =$X3*(H3-$E3) -> -10329.2 | AC3: =$X3*(I3-$E3) -> -14210.4 | AD3: =$X3*(J3-$E3) -> -10726 | AE3: =$X3*(K3-$E3) -> -13131.6 | AG3: 0.2 | AH3: =ROUND(160000*AG3/I3,0) -> 20 | AI3: =AH3*$E3 -> 40732 | AJ3: =$AH3*(F3-$E3) -> -3642 | AK3: =$AH3*(G3-$E3) -> 1964 | AL3: =$AH3*(H3-$E3) -> -6664 | AM3: =$AH3*(I3-$E3) -> -9168 | AN3: =$AH3*(J3-$E3) -> -6920 | AO3: =$AH3*(K3-$E3) -> -8472
A4: 2 | B4: NELCO | C4: TELECOM | D4: Nelco Ltd | E4: 718.4 | F4: 770.3 | G4: 1028 | H4: 1262.3 | I4: 896.3 | J4: 1010.9 | K4: 842.2 | M4: =1/3 -> 0.33333333 | N4: =ROUND(160000*M4/E4,0) -> 74 | O4: =N4*E4 -> 53161.6 | P4: =$N4*(F4-$E4) -> 3840.6 | Q4: =$N4*(G4-$E4) -> 22910.4 | R4: =$N4*(H4-$E4) -> 40248.6 | S4: =$N4*(I4-$E4) -> 13164.6 | T4: =$N4*(J4-$E4) -> 21645 | U4: =$N4*(K4-$E4) -> 9161.2 | W4: 0.2 | X4: =ROUND(160000*W4/E4,0) -> 45 | Y4: =X4*$E4 -> 32328 | Z4: =$X4*(F4-$E4) -> 2335.5 | AA4: =$X4*(G4-$E4) -> 13932 | AB4: =$X4*(H4-$E4) -> 24475.5 | AC4: =$X4*(I4-$E4) -> 8005.5 | AD4: =$X4*(J4-$E4) -> 13162.5 | AE4: =$X4*(K4-$E4) -> 5571 | AG4: 0.4 | AH4: =ROUND(160000*AG4/I4,0) -> 71 | AI4: =AH4*$E4 -> 51006.4 | AJ4: =$AH4*(F4-$E4) -> 3684.9 | AK4: =$AH4*(G4-$E4) -> 21981.6 | AL4: =$AH4*(H4-$E4) -> 38616.9 | AM4: =$AH4*(I4-$E4) -> 12630.9 | AN4: =$AH4*(J4-$E4) -> 20767.5 | AO4: =$AH4*(K4-$E4) -> 8789.8
A5: 3 | B5: INDUSTOWER | C5: TELECOM | D5: Indus Towers Ltd | E5: 315.2 | F5: 375.3 | G5: 392.6 | H5: 341.8 | I5: 352.5 | J5: 421.1 | K5: 342.9 | M5: =1/3 -> 0.33333333 | N5: =ROUND(160000*M5/E5,0) -> 169 | O5: =N5*E5 -> 53268.8 | P5: =$N5*(F5-$E5) -> 10156.9 | Q5: =$N5*(G5-$E5) -> 13080.6 | R5: =$N5*(H5-$E5) -> 4495.4 | S5: =$N5*(I5-$E5) -> 6303.7 | T5: =$N5*(J5-$E5) -> 17897.1 | U5: =$N5*(K5-$E5) -> 4681.3 | W5: 0.4 | X5: =ROUND(160000*W5/E5,0) -> 203 | Y5: =X5*$E5 -> 63985.6 | Z5: =$X5*(F5-$E5) -> 12200.3 | AA5: =$X5*(G5-$E5) -> 15712.2 | AB5: =$X5*(H5-$E5) -> 5399.8 | AC5: =$X5*(I5-$E5) -> 7571.9 | AD5: =$X5*(J5-$E5) -> 21497.7 | AE5: =$X5*(K5-$E5) -> 5623.1 | AG5: 0.4 | AH5: =ROUND(160000*AG5/I5,0) -> 182 | AI5: =AH5*$E5 -> 57366.4 | AJ5: =$AH5*(F5-$E5) -> 10938.2 | AK5: =$AH5*(G5-$E5) -> 14086.8 | AL5: =$AH5*(H5-$E5) -> 4841.2 | AM5: =$AH5*(I5-$E5) -> 6788.6 | AN5: =$AH5*(J5-$E5) -> 19273.8 | AO5: =$AH5*(K5-$E5) -> 5041.4
C6: Total | M6: =SUM(M3:M5) -> 1 | N6: =SUM(N3:N5) -> 269 | O6: =SUM(O3:O5) -> 159382 | P6: =SUM(P3:P5) -> 9262.9 | Q6: =SUM(Q3:Q5) -> 38544.2 | R6: =SUM(R3:R5) -> 36080.8 | S6: =SUM(S3:S5) -> 7549.9 | T6: =SUM(T3:T5) -> 30546.1 | U6: =SUM(U3:U5) -> 2828.9 | W6: =SUM(W3:W5) -> 1 | X6: =SUM(X3:X5) -> 279 | Y6: =SUM(Y3:Y5) -> 159448.2 | Z6: =SUM(Z3:Z5) -> 8890.7 | AA6: =SUM(AA3:AA5) -> 32688.4 | AB6: =SUM(AB3:AB5) -> 19546.1 | AC6: =SUM(AC3:AC5) -> 1367 | AD6: =SUM(AD3:AD5) -> 23934.2 | AE6: =SUM(AE3:AE5) -> -1937.5 | AG6: =SUM(AG3:AG5) -> 1 | AH6: =SUM(AH3:AH5) -> 273 | AI6: =SUM(AI3:AI5) -> 149104.8 | AJ6: =SUM(AJ3:AJ5) -> 10981.1 | AK6: =SUM(AK3:AK5) -> 38032.4 | AL6: =SUM(AL3:AL5) -> 36794.1 | AM6: =SUM(AM3:AM5) -> 10251.5 | AN6: =SUM(AN3:AN5) -> 33121.3 | AO6: =SUM(AO3:AO5) -> 5359.2
A7: 4 | B7: ANTELOPUS | C7: Oil and gas | D7: Antelopus | E7: 459.9 | F7: 731.8 | G7: 845.6 | H7: 819.9 | I7: 573.4 | J7: 694.9 | K7: 551.8 | M7: =1/3 -> 0.33333333 | N7: =ROUND(160000*M7/E7,0) -> 116 | O7: =N7*E7 -> 53348.4 | P7: =$N7*(F7-$E7) -> 31540.4 | Q7: =$N7*(G7-$E7) -> 44741.2 | R7: =$N7*(H7-$E7) -> 41760 | S7: =$N7*(I7-$E7) -> 13166 | T7: =$N7*(J7-$E7) -> 27260 | U7: =$N7*(K7-$E7) -> 10660.4 | W7: 0.4 | X7: =ROUND(160000*W7/E7,0) -> 139 | Y7: =X7*$E7 -> 63926.1 | Z7: =$X7*(F7-$E7) -> 37794.1 | AA7: =$X7*(G7-$E7) -> 53612.3 | AB7: =$X7*(H7-$E7) -> 50040 | AC7: =$X7*(I7-$E7) -> 15776.5 | AD7: =$X7*(J7-$E7) -> 32665 | AE7: =$X7*(K7-$E7) -> 12774.1 | AG7: 0.4 | AH7: =ROUND(160000*AG7/I7,0) -> 112 | AI7: =AH7*$E7 -> 51508.8 | AJ7: =$AH7*(F7-$E7) -> 30452.8 | AK7: =$AH7*(G7-$E7) -> 43198.4 | AL7: =$AH7*(H7-$E7) -> 40320 | AM7: =$AH7*(I7-$E7) -> 12712 | AN7: =$AH7*(J7-$E7) -> 26320 | AO7: =$AH7*(K7-$E7) -> 10292.8
A8: 5 | B8: ONGC | C8: Oil and gas | D8: Oil and Natural Gas Corporation Ltd | E8: 269.9 | F8: 274.2 | G8: 297.6 | H8: 239.3 | I8: 248.1 | J8: 244.2 | K8: 239.5 | M8: =1/3 -> 0.33333333 | N8: =ROUND(160000*M8/E8,0) -> 198 | O8: =N8*E8 -> 53440.2 | P8: =$N8*(F8-$E8) -> 851.4 | Q8: =$N8*(G8-$E8) -> 5484.6 | R8: =$N8*(H8-$E8) -> -6058.8 | S8: =$N8*(I8-$E8) -> -4316.4 | T8: =$N8*(J8-$E8) -> -5088.6 | U8: =$N8*(K8-$E8) -> -6019.2 | W8: 0.4 | X8: =ROUND(160000*W8/E8,0) -> 237 | Y8: =X8*$E8 -> 63966.3 | Z8: =$X8*(F8-$E8) -> 1019.1 | AA8: =$X8*(G8-$E8) -> 6564.9 | AB8: =$X8*(H8-$E8) -> -7252.2 | AC8: =$X8*(I8-$E8) -> -5166.6 | AD8: =$X8*(J8-$E8) -> -6090.9 | AE8: =$X8*(K8-$E8) -> -7204.8 | AG8: 0.2 | AH8: =ROUND(160000*AG8/I8,0) -> 129 | AI8: =AH8*$E8 -> 34817.1 | AJ8: =$AH8*(F8-$E8) -> 554.7 | AK8: =$AH8*(G8-$E8) -> 3573.3 | AL8: =$AH8*(H8-$E8) -> -3947.4 | AM8: =$AH8*(I8-$E8) -> -2812.2 | AN8: =$AH8*(J8-$E8) -> -3315.3 | AO8: =$AH8*(K8-$E8) -> -3921.6
A9: 6 | B9: HINDOILEXP | C9: Oil and gas | D9: Hindustan Oil Exploration Company Ltd | E9: 181.6 | F9: 196 | G9: 231.1 | H9: 183.2 | I9: 172.6 | J9: 167.1 | K9: 170.3 | M9: =1/3 -> 0.33333333 | N9: =ROUND(160000*M9/E9,0) -> 294 | O9: =N9*E9 -> 53390.4 | P9: =$N9*(F9-$E9) -> 4233.6 | Q9: =$N9*(G9-$E9) -> 14553 | R9: =$N9*(H9-$E9) -> 470.4 | S9: =$N9*(I9-$E9) -> -2646 | T9: =$N9*(J9-$E9) -> -4263 | U9: =$N9*(K9-$E9) -> -3322.2 | W9: 0.2 | X9: =ROUND(160000*W9/E9,0) -> 176 | Y9: =X9*$E9 -> 31961.6 | Z9: =$X9*(F9-$E9) -> 2534.4 | AA9: =$X9*(G9-$E9) -> 8712 | AB9: =$X9*(H9-$E9) -> 281.6 | AC9: =$X9*(I9-$E9) -> -1584 | AD9: =$X9*(J9-$E9) -> -2552 | AE9: =$X9*(K9-$E9) -> -1988.8 | AG9: 0.4 | AH9: =ROUND(160000*AG9/I9,0) -> 371 | AI9: =AH9*$E9 -> 67373.6 | AJ9: =$AH9*(F9-$E9) -> 5342.4 | AK9: =$AH9*(G9-$E9) -> 18364.5 | AL9: =$AH9*(H9-$E9) -> 593.6 | AM9: =$AH9*(I9-$E9) -> -3339 | AN9: =$AH9*(J9-$E9) -> -5379.5 | AO9: =$AH9*(K9-$E9) -> -4192.3
C10: Total | M10: =SUM(M7:M9) -> 1 | N10: =SUM(N7:N9) -> 608 | O10: =SUM(O7:O9) -> 160179 | P10: =SUM(P7:P9) -> 36625.4 | Q10: =SUM(Q7:Q9) -> 64778.8 | R10: =SUM(R7:R9) -> 36171.6 | S10: =SUM(S7:S9) -> 6203.6 | T10: =SUM(T7:T9) -> 17908.4 | U10: =SUM(U7:U9) -> 1319 | W10: =SUM(W7:W9) -> 1 | X10: =SUM(X7:X9) -> 552 | Y10: =SUM(Y7:Y9) -> 159854 | Z10: =SUM(Z7:Z9) -> 41347.6 | AA10: =SUM(AA7:AA9) -> 68889.2 | AB10: =SUM(AB7:AB9) -> 43069.4 | AC10: =SUM(AC7:AC9) -> 9025.9 | AD10: =SUM(AD7:AD9) -> 24022.1 | AE10: =SUM(AE7:AE9) -> 3580.5 | AG10: =SUM(AG7:AG9) -> 1 | AH10: =SUM(AH7:AH9) -> 612 | AI10: =SUM(AI7:AI9) -> 153699.5 | AJ10: =SUM(AJ7:AJ9) -> 36349.9 | AK10: =SUM(AK7:AK9) -> 65136.2 | AL10: =SUM(AL7:AL9) -> 36966.2 | AM10: =SUM(AM7:AM9) -> 6560.8 | AN10: =SUM(AN7:AN9) -> 17625.2 | AO10: =SUM(AO7:AO9) -> 2178.9
A11: 7 | B11: TTKPRESTIG | C11: Consumer Electronics | D11: TTK Prestige Ltd | E11: 692.5 | F11: 786.8 | G11: 875.4 | H11: 809.9 | I11: 612.7 | J11: 624.4 | K11: 635.2 | M11: =1/3 -> 0.33333333 | N11: =ROUND(160000*M11/E11,0) -> 77 | O11: =N11*E11 -> 53322.5 | P11: =$N11*(F11-$E11) -> 7261.1 | Q11: =$N11*(G11-$E11) -> 14083.3 | R11: =$N11*(H11-$E11) -> 9039.8 | S11: =$N11*(I11-$E11) -> -6144.6 | T11: =$N11*(J11-$E11) -> -5243.7 | U11: =$N11*(K11-$E11) -> -4412.1 | W11: 0.4 | X11: =ROUND(160000*W11/E11,0) -> 92 | Y11: =X11*$E11 -> 63710 | Z11: =$X11*(F11-$E11) -> 8675.6 | AA11: =$X11*(G11-$E11) -> 16826.8 | AB11: =$X11*(H11-$E11) -> 10800.8 | AC11: =$X11*(I11-$E11) -> -7341.6 | AD11: =$X11*(J11-$E11) -> -6265.2 | AE11: =$X11*(K11-$E11) -> -5271.6 | AG11: 0.4 | AH11: =ROUND(160000*AG11/I11,0) -> 104 | AI11: =AH11*$E11 -> 72020 | AJ11: =$AH11*(F11-$E11) -> 9807.2 | AK11: =$AH11*(G11-$E11) -> 19021.6 | AL11: =$AH11*(H11-$E11) -> 12209.6 | AM11: =$AH11*(I11-$E11) -> -8299.2 | AN11: =$AH11*(J11-$E11) -> -7082.4 | AO11: =$AH11*(K11-$E11) -> -5959.2
A12: 8 | B12: VOLTAS | C12: Consumer Electronics | D12: Voltas Ltd | E12: 1151.6 | F12: 1472.2 | G12: 1845.1 | H12: 1790 | I12: 1352.1 | J12: 1314.1 | K12: 1354 | M12: =1/3 -> 0.33333333 | N12: =ROUND(160000*M12/E12,0) -> 46 | O12: =N12*E12 -> 52973.6 | P12: =$N12*(F12-$E12) -> 14747.6 | Q12: =$N12*(G12-$E12) -> 31901 | R12: =$N12*(H12-$E12) -> 29366.4 | S12: =$N12*(I12-$E12) -> 9223 | T12: =$N12*(J12-$E12) -> 7475 | U12: =$N12*(K12-$E12) -> 9310.4 | W12: 0.4 | X12: =ROUND(160000*W12/E12,0) -> 56 | Y12: =X12*$E12 -> 64489.6 | Z12: =$X12*(F12-$E12) -> 17953.6 | AA12: =$X12*(G12-$E12) -> 38836 | AB12: =$X12*(H12-$E12) -> 35750.4 | AC12: =$X12*(I12-$E12) -> 11228 | AD12: =$X12*(J12-$E12) -> 9100 | AE12: =$X12*(K12-$E12) -> 11334.4 | AG12: 0.2 | AH12: =ROUND(160000*AG12/I12,0) -> 24 | AI12: =AH12*$E12 -> 27638.4 | AJ12: =$AH12*(F12-$E12) -> 7694.4 | AK12: =$AH12*(G12-$E12) -> 16644 | AL12: =$AH12*(H12-$E12) -> 15321.6 | AM12: =$AH12*(I12-$E12) -> 4812 | AN12: =$AH12*(J12-$E12) -> 3900 | AO12: =$AH12*(K12-$E12) -> 4857.6
A13: 9 | B13: WHR | C13: Consumer Electronics | D13: Whirlpool of India Ltd | E13: 119.2 | F13: 87.03 | G13: 102.7 | H13: 114.5 | I13: 91.2 | J13: 93 | K13: 81.09 | M13: =1/3 -> 0.33333333 | N13: =ROUND(160000*M13/E13,0) -> 447 | O13: =N13*E13 -> 53282.4 | P13: =$N13*(F13-$E13) -> -14379.99 | Q13: =$N13*(G13-$E13) -> -7375.5 | R13: =$N13*(H13-$E13) -> -2100.9 | S13: =$N13*(I13-$E13) -> -12516 | T13: =$N13*(J13-$E13) -> -11711.4 | U13: =$N13*(K13-$E13) -> -17035.17 | W13: 0.2 | X13: =ROUND(160000*W13/E13,0) -> 268 | Y13: =X13*$E13 -> 31945.6 | Z13: =$X13*(F13-$E13) -> -8621.56 | AA13: =$X13*(G13-$E13) -> -4422 | AB13: =$X13*(H13-$E13) -> -1259.6 | AC13: =$X13*(I13-$E13) -> -7504 | AD13: =$X13*(J13-$E13) -> -7021.6 | AE13: =$X13*(K13-$E13) -> -10213.48 | AG13: 0.4 | AH13: =ROUND(160000*AG13/I13,0) -> 702 | AI13: =AH13*$E13 -> 83678.4 | AJ13: =$AH13*(F13-$E13) -> -22583.34 | AK13: =$AH13*(G13-$E13) -> -11583 | AL13: =$AH13*(H13-$E13) -> -3299.4 | AM13: =$AH13*(I13-$E13) -> -19656 | AN13: =$AH13*(J13-$E13) -> -18392.4 | AO13: =$AH13*(K13-$E13) -> -26753.22
C14: Total | M14: =SUM(M11:M13) -> 1 | N14: =SUM(N11:N13) -> 570 | O14: =SUM(O11:O13) -> 159578.5 | P14: =SUM(P11:P13) -> 7628.71 | Q14: =SUM(Q11:Q13) -> 38608.8 | R14: =SUM(R11:R13) -> 36305.3 | S14: =SUM(S11:S13) -> -9437.6 | T14: =SUM(T11:T13) -> -9480.1 | U14: =SUM(U11:U13) -> -12136.87 | W14: =SUM(W11:W13) -> 1 | X14: =SUM(X11:X13) -> 416 | Y14: =SUM(Y11:Y13) -> 160145.2 | Z14: =SUM(Z11:Z13) -> 18007.64 | AA14: =SUM(AA11:AA13) -> 51240.8 | AB14: =SUM(AB11:AB13) -> 45291.6 | AC14: =SUM(AC11:AC13) -> -3617.6 | AD14: =SUM(AD11:AD13) -> -4186.8 | AE14: =SUM(AE11:AE13) -> -4150.68 | AG14: =SUM(AG11:AG13) -> 1 | AH14: =SUM(AH11:AH13) -> 830 | AI14: =SUM(AI11:AI13) -> 183336.8 | AJ14: =SUM(AJ11:AJ13) -> -5081.74 | AK14: =SUM(AK11:AK13) -> 24082.6 | AL14: =SUM(AL11:AL13) -> 24231.8 | AM14: =SUM(AM11:AM13) -> -23143.2 | AN14: =SUM(AN11:AN13) -> -21574.8 | AO14: =SUM(AO11:AO13) -> -27854.82
A15: 10 | B15: MAITHANALL | C15: Metal | D15: Maithan Alloys Ltd | E15: 1021.3 | F15: 1190.3 | G15: 1158.1 | H15: 1119.2 | I15: 909.15 | J15: 1232.4 | K15: 1099 | M15: =1/3 -> 0.33333333 | N15: =ROUND(160000*M15/E15,0) -> 52 | O15: =N15*E15 -> 53107.6 | P15: =$N15*(F15-$E15) -> 8788 | Q15: =$N15*(G15-$E15) -> 7113.6 | R15: =$N15*(H15-$E15) -> 5090.8 | S15: =$N15*(I15-$E15) -> -5831.8 | T15: =$N15*(J15-$E15) -> 10977.2 | U15: =$N15*(K15-$E15) -> 4040.4 | W15: 0.2 | X15: =ROUND(160000*W15/E15,0) -> 31 | Y15: =X15*$E15 -> 31660.3 | Z15: =$X15*(F15-$E15) -> 5239 | AA15: =$X15*(G15-$E15) -> 4240.8 | AB15: =$X15*(H15-$E15) -> 3034.9 | AC15: =$X15*(I15-$E15) -> -3476.65 | AD15: =$X15*(J15-$E15) -> 6544.1 | AE15: =$X15*(K15-$E15) -> 2408.7 | AG15: 0.4 | AH15: =ROUND(160000*AG15/I15,0) -> 70 | AI15: =AH15*$E15 -> 71491 | AJ15: =$AH15*(F15-$E15) -> 11830 | AK15: =$AH15*(G15-$E15) -> 9576 | AL15: =$AH15*(H15-$E15) -> 6853 | AM15: =$AH15*(I15-$E15) -> -7850.5 | AN15: =$AH15*(J15-$E15) -> 14777 | AO15: =$AH15*(K15-$E15) -> 5439
A16: 11 | B16: SARDAEN | C16: Metal | D16: Sarda Energy & Minerals Ltd | E16: 207.1 | F16: 232.6 | G16: 443 | H16: 482.7 | I16: 528.1 | J16: 443.4 | K16: 539.4 | M16: =1/3 -> 0.33333333 | N16: =ROUND(160000*M16/E16,0) -> 258 | O16: =N16*E16 -> 53431.8 | P16: =$N16*(F16-$E16) -> 6579 | Q16: =$N16*(G16-$E16) -> 60862.2 | R16: =$N16*(H16-$E16) -> 71104.8 | S16: =$N16*(I16-$E16) -> 82818 | T16: =$N16*(J16-$E16) -> 60965.4 | U16: =$N16*(K16-$E16) -> 85733.4 | W16: 0.4 | X16: =ROUND(160000*W16/E16,0) -> 309 | Y16: =X16*$E16 -> 63993.9 | Z16: =$X16*(F16-$E16) -> 7879.5 | AA16: =$X16*(G16-$E16) -> 72893.1 | AB16: =$X16*(H16-$E16) -> 85160.4 | AC16: =$X16*(I16-$E16) -> 99189 | AD16: =$X16*(J16-$E16) -> 73016.7 | AE16: =$X16*(K16-$E16) -> 102680.7 | AG16: 0.4 | AH16: =ROUND(160000*AG16/I16,0) -> 121 | AI16: =AH16*$E16 -> 25059.1 | AJ16: =$AH16*(F16-$E16) -> 3085.5 | AK16: =$AH16*(G16-$E16) -> 28543.9 | AL16: =$AH16*(H16-$E16) -> 33347.6 | AM16: =$AH16*(I16-$E16) -> 38841 | AN16: =$AH16*(J16-$E16) -> 28592.3 | AO16: =$AH16*(K16-$E16) -> 40208.3
A17: 12 | B17: TATASTEEL | C17: Metal | D17: Tata Steel Ltd | E17: 163.2 | F17: 174 | G17: 168.6 | H17: 138.1 | I17: 153.1 | J17: 159.8 | K17: 168.8 | M17: =1/3 -> 0.33333333 | N17: =ROUND(160000*M17/E17,0) -> 327 | O17: =N17*E17 -> 53366.4 | P17: =$N17*(F17-$E17) -> 3531.6 | Q17: =$N17*(G17-$E17) -> 1765.8 | R17: =$N17*(H17-$E17) -> -8207.7 | S17: =$N17*(I17-$E17) -> -3302.7 | T17: =$N17*(J17-$E17) -> -1111.8 | U17: =$N17*(K17-$E17) -> 1831.2 | W17: 0.4 | X17: =ROUND(160000*W17/E17,0) -> 392 | Y17: =X17*$E17 -> 63974.4 | Z17: =$X17*(F17-$E17) -> 4233.6 | AA17: =$X17*(G17-$E17) -> 2116.8 | AB17: =$X17*(H17-$E17) -> -9839.2 | AC17: =$X17*(I17-$E17) -> -3959.2 | AD17: =$X17*(J17-$E17) -> -1332.8 | AE17: =$X17*(K17-$E17) -> 2195.2 | AG17: 0.2 | AH17: =ROUND(160000*AG17/I17,0) -> 209 | AI17: =AH17*$E17 -> 34108.8 | AJ17: =$AH17*(F17-$E17) -> 2257.2 | AK17: =$AH17*(G17-$E17) -> 1128.6 | AL17: =$AH17*(H17-$E17) -> -5245.9 | AM17: =$AH17*(I17-$E17) -> -2110.9 | AN17: =$AH17*(J17-$E17) -> -710.6 | AO17: =$AH17*(K17-$E17) -> 1170.4
C18: Total | M18: =SUM(M15:M17) -> 1 | N18: =SUM(N15:N17) -> 637 | O18: =SUM(O15:O17) -> 159905.8 | P18: =SUM(P15:P17) -> 18898.6 | Q18: =SUM(Q15:Q17) -> 69741.6 | R18: =SUM(R15:R17) -> 67987.9 | S18: =SUM(S15:S17) -> 73683.5 | T18: =SUM(T15:T17) -> 70830.8 | U18: =SUM(U15:U17) -> 91605 | W18: =SUM(W15:W17) -> 1 | X18: =SUM(X15:X17) -> 732 | Y18: =SUM(Y15:Y17) -> 159628.6 | Z18: =SUM(Z15:Z17) -> 17352.1 | AA18: =SUM(AA15:AA17) -> 79250.7 | AB18: =SUM(AB15:AB17) -> 78356.1 | AC18: =SUM(AC15:AC17) -> 91753.15 | AD18: =SUM(AD15:AD17) -> 78228 | AE18: =SUM(AE15:AE17) -> 107284.6 | AH18: =SUM(AH15:AH17) -> 400 | AI18: =SUM(AI15:AI17) -> 130658.9 | AJ18: =SUM(AJ15:AJ17) -> 17172.7 | AK18: =SUM(AK15:AK17) -> 39248.5 | AL18: =SUM(AL15:AL17) -> 34954.7 | AM18: =SUM(AM15:AM17) -> 28879.6 | AN18: =SUM(AN15:AN17) -> 42658.7 | AO18: =SUM(AO15:AO17) -> 46817.7
A19: 13 | B19: WELENT | C19: Construction | D19: Welspun Enterprises Ltd | E19: 312 | F19: 449.2 | G19: 557.8 | H19: 614.4 | I19: 500.4 | J19: 541 | K19: 499.5 | M19: =1/3 -> 0.33333333 | N19: =ROUND(160000*M19/E19,0) -> 171 | O19: =N19*E19 -> 53352 | P19: =$N19*(F19-$E19) -> 23461.2 | Q19: =$N19*(G19-$E19) -> 42031.8 | R19: =$N19*(H19-$E19) -> 51710.4 | S19: =$N19*(I19-$E19) -> 32216.4 | T19: =$N19*(J19-$E19) -> 39159 | U19: =$N19*(K19-$E19) -> 32062.5 | W19: 0.4 | X19: =ROUND(160000*W19/E19,0) -> 205 | Y19: =X19*$E19 -> 63960 | Z19: =$X19*(F19-$E19) -> 28126 | AA19: =$X19*(G19-$E19) -> 50389 | AB19: =$X19*(H19-$E19) -> 61992 | AC19: =$X19*(I19-$E19) -> 38622 | AD19: =$X19*(J19-$E19) -> 46945 | AE19: =$X19*(K19-$E19) -> 38437.5 | AG19: 0.4 | AH19: =ROUND(160000*AG19/I19,0) -> 128 | AI19: =AH19*$E19 -> 39936 | AJ19: =$AH19*(F19-$E19) -> 17561.6 | AK19: =$AH19*(G19-$E19) -> 31462.4 | AL19: =$AH19*(H19-$E19) -> 38707.2 | AM19: =$AH19*(I19-$E19) -> 24115.2 | AN19: =$AH19*(J19-$E19) -> 29312 | AO19: =$AH19*(K19-$E19) -> 24000
A20: 14 | B20: INDIANHUME | C20: Construction | D20: The Indian Hume Pipe Company Ltd | E20: 278.5 | F20: 434.1 | G20: 493.5 | H20: 360.2 | I20: 367.1 | J20: 333.34615 | K20: 358.9 | M20: =1/3 -> 0.33333333 | N20: =ROUND(160000*M20/E20,0) -> 192 | O20: =N20*E20 -> 53472 | P20: =$N20*(F20-$E20) -> 29875.2 | Q20: =$N20*(G20-$E20) -> 41280 | R20: =$N20*(H20-$E20) -> 15686.4 | S20: =$N20*(I20-$E20) -> 17011.2 | T20: =$N20*(J20-$E20) -> 10530.462 | U20: =$N20*(K20-$E20) -> 15436.8 | W20: 0.2 | X20: =ROUND(160000*W20/E20,0) -> 115 | Y20: =X20*$E20 -> 32027.5 | Z20: =$X20*(F20-$E20) -> 17894 | AA20: =$X20*(G20-$E20) -> 24725 | AB20: =$X20*(H20-$E20) -> 9395.5 | AC20: =$X20*(I20-$E20) -> 10189 | AD20: =$X20*(J20-$E20) -> 6307.3077 | AE20: =$X20*(K20-$E20) -> 9246 | AG20: 0.2 | AH20: =ROUND(160000*AG20/I20,0) -> 87 | AI20: =AH20*$E20 -> 24229.5 | AJ20: =$AH20*(F20-$E20) -> 13537.2 | AK20: =$AH20*(G20-$E20) -> 18705 | AL20: =$AH20*(H20-$E20) -> 7107.9 | AM20: =$AH20*(I20-$E20) -> 7708.2 | AN20: =$AH20*(J20-$E20) -> 4771.6154 | AO20: =$AH20*(K20-$E20) -> 6994.8
A21: 15 | B21: JINDRILL | C21: Construction | D21: Jindal Drilling & Industries Ltd | E21: 634.4 | F21: 635.8 | G21: 616.8 | H21: 771 | I21: 876.7 | J21: 286.05604 | K21: 594.4 | M21: =1/3 -> 0.33333333 | N21: =ROUND(160000*M21/E21,0) -> 84 | O21: =N21*E21 -> 53289.6 | P21: =$N21*(F21-$E21) -> 117.6 | Q21: =$N21*(G21-$E21) -> -1478.4 | R21: =$N21*(H21-$E21) -> 11474.4 | S21: =$N21*(I21-$E21) -> 20353.2 | T21: =$N21*(J21-$E21) -> -29260.892 | U21: =$N21*(K21-$E21) -> -3360 | W21: 0.4 | X21: =ROUND(160000*W21/E21,0) -> 101 | Y21: =X21*$E21 -> 64074.4 | Z21: =$X21*(F21-$E21) -> 141.4 | AA21: =$X21*(G21-$E21) -> -1777.6 | AB21: =$X21*(H21-$E21) -> 13796.6 | AC21: =$X21*(I21-$E21) -> 24472.3 | AD21: =$X21*(J21-$E21) -> -35182.74 | AE21: =$X21*(K21-$E21) -> -4040 | AG21: 0.4 | AH21: =ROUND(160000*AG21/I21,0) -> 73 | AI21: =AH21*$E21 -> 46311.2 | AJ21: =$AH21*(F21-$E21) -> 102.2 | AK21: =$AH21*(G21-$E21) -> -1284.8 | AL21: =$AH21*(H21-$E21) -> 9971.8 | AM21: =$AH21*(I21-$E21) -> 17687.9 | AN21: =$AH21*(J21-$E21) -> -25429.109 | AO21: =$AH21*(K21-$E21) -> -2920
A22: Total | M22: =SUM(M19:M21) -> 1 | N22: =SUM(N19:N21) -> 447 | O22: =SUM(O19:O21) -> 160113.6 | P22: =SUM(P19:P21) -> 53454 | Q22: =SUM(Q19:Q21) -> 81833.4 | R22: =SUM(R19:R21) -> 78871.2 | S22: =SUM(S19:S21) -> 69580.8 | T22: =SUM(T19:T21) -> 20428.569 | U22: =SUM(U19:U21) -> 44139.3 | W22: =SUM(W19:W21) -> 1 | X22: =SUM(X19:X21:X21) -> 421 | Y22: =SUM(Y19:Y21) -> 160061.9 | Z22: =SUM(Z19:Z21) -> 46161.4 | AA22: =SUM(AA19:AA21) -> 73336.4 | AB22: =SUM(AB19:AB21) -> 85184.1 | AC22: =SUM(AC19:AC21) -> 73283.3 | AD22: =SUM(AD19:AD21) -> 18069.568 | AE22: =SUM(AE19:AE21) -> 43643.5 | AG22: =SUM(AG19:AG21) -> 1 | AH22: =SUM(AH19:AH21) -> 288 | AI22: =SUM(AI3:AI21) -> 1344076.7 | AJ22: =SUM(AJ3:AJ21) -> 150044.92 | AK22: =SUM(AK3:AK21) -> 381882 | AL22: =SUM(AL3:AL21) -> 321680.5 | AM22: =SUM(AM3:AM21) -> 94608.7 | AN22: =SUM(AN3:AN21) -> 152315.31 | AO22: =SUM(AO19:AO21) -> 28074.8
T24: Combined Total | U24: =SUM(U6,U10,U14,U18,U22) -> 127755.33 | AD24: Combined Total | AE24: =SUM(AE6,AE10,AE14,AE18,AE22) -> 148420.42 | AN24: Combined Total | AO24: =SUM(AO6,AO10,AO14,AO18,AO22) -> 54575.78

Sheet TELECOM MAX PROFIT
A2: ASSETS | B2: Expected returns | C2: St.Deviation | D2: Min Weight | E2: Max Weight | F2: weight | J2: TATA COMMUNICATION | K2: NELCO | L2: INDUSTOWER
A3: TATA COMMUNICATION | B3: 0.0024448301 | C3: 0.02407353 | D3: 0.02 | E3: 0.4 | F3: 0.4 | I3: TATA COMMUNICATION | J3: =VARP([1]Sheet1!$A$3:$A$986) -> 0.00057894588 | K3: 0.00016516084 | L3: 0.00016516084
A4: NELCO | B4: 0.0021464261 | C4: 0.030885191 | D4: 0.02 | E4: 0.4 | F4: 0.2 | I4: NELCO | J4: 0.00016516084 | K4: =VARP([1]Sheet1!$B$3:$B$986) -> 0.00095292564 | L4: 0.00095292564
A5: INDUSTOWER | B5: 0.0021464261 | C5: 0.030885191 | D5: 0.02 | E5: 0.4 | F5: 0.4 | I5: INDUSTOWER | J5: 0.00016516084 | K5: 0.00095292564 | L5: =VARP([1]Sheet1!$C$3:$C$986) -> 0.00095292564
A20: Risk Free rate | B20: =C20/365 -> 0.00019178082 | C20: 0.07
A21: Sharp Ratio | B21: =B22-B20/B23 -> -0.0061853987
A22: Expected returns | B22: =SUMPRODUCT(B3:B5,F3:F5) -> 0.0022657877 | C22: =B22*252 -> 0.57097851
A23: Risk (Portfolio) | B23: {=SQRT(MMULT(TRANSPOSE(F3:F5),MMULT(J3:L5,F3:F5)))} -> 0.022692769
A24: Total | B24: =SUM(F3:F17) -> 1

Sheet TELECOM SHARPE 
A2: ASSETS | B2: Expected returns | C2: St.Deviation | D2: Min Weight | E2: Max Weight | F2: weight | J2: TATA COMMUNICATION | K2: NELCO | L2: INDUSTOWER
A3: TATA COMMUNICATION | B3: 0.0024448301 | C3: 0.02407353 | D3: 0.02 | E3: 0.4 | F3: 0.2 | I3: TATA COMMUNICATION | J3: =VARP([1]Sheet1!$A$3:$A$986) -> 0.00057894588 | K3: 0.00016516084 | L3: 0.00016516084
A4: NELCO | B4: 0.0021464261 | C4: 0.030885191 | D4: 0.02 | E4: 0.4 | F4: 0.4 | I4: NELCO | J4: 0.00016516084 | K4: =VARP([1]Sheet1!$B$3:$B$986) -> 0.00095292564 | L4: 0.00095292564
A5: INDUSTOWER | B5: 0.0021464261 | C5: 0.030885191 | D5: 0.02 | E5: 0.4 | F5: 0.4 | I5: INDUSTOWER | J5: 0.00016516084 | K5: 0.00095292564 | L5: =VARP([1]Sheet1!$C$3:$C$986) -> 0.00095292564
A20: Risk Free rate | B20: =C20/365 -> 0.00019178082 | C20: 0.07
A21: Sharp Ratio | B21: =B22-B20/B23 -> -0.0051167503
A22: Expected returns | B22: =SUMPRODUCT(B3:B5,F3:F5) -> 0.0022061069 | C22: =B22*252 -> 0.55593894
A23: Risk (Portfolio) | B23: {=SQRT(MMULT(TRANSPOSE(F3:F5),MMULT(J3:L5,F3:F5)))} -> 0.026189343
A24: Total | B24: =SUM(F3:F17) -> 1

Sheet OIL MAX SHARPE
A2: ASSETS | B2: Expected returns | C2: St.Deviation | D2: Min Weight | E2: Max Weight | F2: weight | J2: ANTELOPUS | K2: ONGC | L2: HINDOILEXP
A3: ANTELOPUS | B3: 0.0024371922 | C3: 0.031773369 | D3: 0.02 | E3: 0.4 | F3: 0.4 | I3: ANTELOPUS | J3: =VARP([1]Sheet1!$F$3:$F$986) -> 0.001008521 | K3: 0.00018582472 | L3: 0.00032669343
A4: ONGC | B4: 0.0016580697 | C4: 0.021902873 | D4: 0.02 | E4: 0.4 | F4: 0.2 | I4: ONGC | J4: 0.00018582472 | K4: =VARP([1]Sheet1!$G$3:$G$986) -> 0.00047924829 | L4: 0.00025885668
A5: HINDOILEXP | B5: 0.0021712349 | C5: 0.033689403 | D5: 0.02 | E5: 0.4 | F5: 0.4 | I5: HINDOILEXP | J5: 0.00032669343 | K5: 0.00025885668 | L5: =VARP([1]Sheet1!$H$3:$H$986) -> 0.0011338224
A20: Risk Free rate | B20: =C20/365 -> 0.00019178082 | C20: 0.07
A21: Sharp Ratio | B21: =B22-B20/B23 -> -0.0060960736
A22: Expected returns | B22: =SUMPRODUCT(B3:B5,F3:F5) -> 0.0021749848 | C22: =B22*252 -> 0.54809616
A23: Risk (Portfolio) | B23: {=SQRT(MMULT(TRANSPOSE(F3:F5),MMULT(J3:L5,F3:F5)))} -> 0.023186975
A24: Total | B24: =SUM(F3:F17) -> 1

Sheet OIL MAX PROFIT
A2: ASSETS | B2: Expected returns | C2: St.Deviation | D2: Min Weight | E2: Max Weight | F2: weight | J2: ANTELOPUS | K2: ONGC | L2: HINDOILEXP
A3: TTKPRESTIG | B3: 0.00058635972 | C3: 0.021112772 | D3: 0.02 | E3: 0.4 | F3: 0.4 | I3: ANTELOPUS | J3: =VARP([1]Sheet1!$F$3:$F$986) -> 0.001008521 | K3: 0.00018582472 | L3: 0.00032669343
A4: VOLTAS | B4: 0.0010325124 | C4: 0.018865176 | D4: 0.02 | E4: 0.4 | F4: 0.4 | I4: ONGC | J4: 0.00018582472 | K4: =VARP([1]Sheet1!$G$3:$G$986) -> 0.00047924829 | L4: 0.00025885668
A5: WHR | B5: 0.00055660205 | C5: 0.022957518 | D5: 0.02 | E5: 0.4 | F5: 0.2 | I5: HINDOILEXP | J5: 0.00032669343 | K5: 0.00025885668 | L5: =VARP([1]Sheet1!$H$3:$H$986) -> 0.0011338224
A20: Risk Free rate | B20: =C20/365 -> 0.00019178082 | C20: 0.07
A21: Sharp Ratio | B21: =B22-B20/B23 -> -0.0084200007
A22: Expected returns | B22: =SUMPRODUCT(B3:B5,F3:F5) -> 0.00075886926 | C22: =B22*252 -> 0.19123505
A23: Risk (Portfolio) | B23: {=SQRT(MMULT(TRANSPOSE(F3:F5),MMULT(J3:L5,F3:F5)))} -> 0.020893729
A24: Total | B24: =SUM(F3:F17) -> 1

Sheet COMSUMER MAX PROFIT
A2: ASSETS | B2: Expected returns | C2: St.Deviation | D2: Min Weight | E2: Max Weight | F2: weight | J2: TTKPRESTIG | K2: VOLTAS | L2: WHR
A3: TTKPRESTIG | B3: 0.00058635972 | C3: 0.021112772 | D3: 0.02 | E3: 0.4 | F3: 0.4 | I3: TTKPRESTIG | J3: =VARP([1]Sheet1!$J$3:$J$986) -> 0.00044529613 | K3: 8.1027214e-05 | L3: -2.2564534e-06
A4: VOLTAS | B4: 0.0010325124 | C4: 0.018865176 | D4: 0.02 | E4: 0.4 | F4: 0.4 | I4: VOLTAS | J4: 8.1027214e-05 | K4: =VARP([1]Sheet1!$K$3:$K$986) -> 0.00035553317 | L4: -9.6193066e-06
A5: WHR | B5: 0.00055660205 | C5: 0.022957518 | D5: 0.02 | E5: 0.4 | F5: 0.2 | I5: WHR | J5: -2.2564534e-06 | K5: -9.6193066e-06 | L5: =VARP([1]Sheet1!$L$3:$L$986) -> 0.00052651201
A20: Risk Free rate | B20: =C20/365 -> 0.00019178082 | C20: 0.07
A21: Sharp Ratio | B21: =B22-B20/B23 -> -0.013812621
A22: Expected returns | B22: =SUMPRODUCT(B3:B5,F3:F5) -> 0.00075886926 | C22: =B22*252 -> 0.19123505
A23: Risk (Portfolio) | B23: {=SQRT(MMULT(TRANSPOSE(F3:F5),MMULT(J3:L5,F3:F5)))} -> 0.013161374
A24: Total | B24: =SUM(F3:F17) -> 1

Sheet CONSUMER SHARPE
A2: ASSETS | B2: Expected returns | C2: St.Deviation | D2: Min Weight | E2: Max Weight | F2: weight | J2: TTKPRESTIG | K2: VOLTAS | L2: WHR
A3: TTKPRESTIG | B3: 0.00058635972 | C3: 0.021112772 | D3: 0.02 | E3: 0.4 | F3: 0.4 | I3: TTKPRESTIG | J3: =VARP([1]Sheet1!$J$3:$J$986) -> 0.00044529613 | K3: 8.1027214e-05 | L3: -2.2564534e-06
A4: VOLTAS | B4: 0.0010325124 | C4: 0.018865176 | D4: 0.02 | E4: 0.4 | F4: 0.2 | I4: VOLTAS | J4: 8.1027214e-05 | K4: =VARP([1]Sheet1!$K$3:$K$986) -> 0.00035553317 | L4: -9.6193066e-06
A5: WHR | B5: 0.00055660205 | C5: 0.022957518 | D5: 0.02 | E5: 0.4 | F5: 0.4 | I5: WHR | J5: -2.2564534e-06 | K5: -9.6193066e-06 | L5: =VARP([1]Sheet1!$L$3:$L$986) -> 0.00052651201
A20: Risk Free rate | B20: =C20/365 -> 0.00019178082 | C20: 0.07
A21: Sharp Ratio | B21: =B22-B20/B23 -> -0.013614408
A22: Expected returns | B22: =SUMPRODUCT(B3:B5,F3:F5) -> 0.00066368719 | C22: =B22*252 -> 0.16724917
A23: Risk (Portfolio) | B23: {=SQRT(MMULT(TRANSPOSE(F3:F5),MMULT(J3:L5,F3:F5)))} -> 0.013431822
A24: Total | B24: =SUM(F3:F17) -> 1

Sheet CONSTRUCTION  MAX SHARP
A2: ASSETS | B2: Expected returns | C2: St.Deviation | D2: Min Weight | E2: Max Weight | F2: weight | I2: ` | J2: WELENT | K2: INDIANHUME | L2: JINDRILL
A3: WELENT | B3: 0.002491596 | C3: 0.029235778 | D3: 0.02 | E3: 0.4 | F3: 0.4 | I3: WELENT | J3: =VARP([2]Sheet1!$E$3:$E$986) -> 0.00085386206 | K3: 0.00025073953 | L3: 0.00016396351
A4: INDIANHUME | B4: 0.001152138 | C4: 0.028090107 | D4: 0.02 | E4: 0.4 | F4: 0.2 | I4: INDIANHUME | J4: 0.00025073953 | K4: =VARP([2]Sheet1!$F$3:$F$986) -> 0.00078825221 | L4: 0.00019236754
A5: JINDRILL | B5: 0.0032882935 | C5: 0.033464593 | D5: 0.02 | E5: 0.4 | F5: 0.4 | I5: JINDRILL | J5: 0.00016396351 | K5: 0.00019236754 | L5: =VARP([2]Sheet1!$G$3:$G$986) -> 0.0011187409
A20: Risk Free rate | B20: =C20/365 -> 0.00019178082 | C20: 0.07
A21: Sharp Ratio | B21: =B22-B20/B23 -> -0.0062989917
A22: Expected returns | B22: =SUMPRODUCT(B3:B5,F3:F5) -> 0.0025423834 | C22: =B22*252 -> 0.64068062
A23: Risk (Portfolio) | B23: {=SQRT(MMULT(TRANSPOSE(F3:F5),MMULT(J3:L5,F3:F5)))} -> 0.021691289
A24: Total | B24: =SUM(F3:F17) -> 1

Sheet CONSTRUCTION MAX PROFIT 
A2: ASSETS | B2: Expected returns | C2: St.Deviation | D2: Min Weight | E2: Max Weight | F2: weight | I2: ` | J2: WELENT | K2: INDIANHUME | L2: JINDRILL
A3: WELENT | B3: 0.002491596 | C3: 0.029235778 | D3: 0.02 | E3: 0.4 | F3: 0.4 | I3: WELENT | J3: =VARP([2]Sheet1!$E$3:$E$986) -> 0.00085386206 | K3: 0.00025073953 | L3: 0.00016396351
A4: INDIANHUME | B4: 0.001152138 | C4: 0.028090107 | D4: 0.02 | E4: 0.4 | F4: 0.2 | I4: INDIANHUME | J4: 0.00025073953 | K4: =VARP([2]Sheet1!$F$3:$F$986) -> 0.00078825221 | L4: 0.00019236754
A5: JINDRILL | B5: 0.0032882935 | C5: 0.033464593 | D5: 0.02 | E5: 0.4 | F5: 0.4 | I5: JINDRILL | J5: 0.00016396351 | K5: 0.00019236754 | L5: =VARP([2]Sheet1!$G$3:$G$986) -> 0.0011187409
A20: Risk Free rate | B20: =C20/365 -> 0.00019178082 | C20: 0.07
A21: Sharp Ratio | B21: =B22-B20/B23 -> -0.0062989917
A22: Expected returns | B22: =SUMPRODUCT(B3:B5,F3:F5) -> 0.0025423834 | C22: =B22*252 -> 0.64068062
A23: Risk (Portfolio) | B23: {=SQRT(MMULT(TRANSPOSE(F3:F5),MMULT(J3:L5,F3:F5)))} -> 0.021691289
A24: Total | B24: =SUM(F3:F17) -> 1

Sheet METALS MAX SHARP
A2: ASSETS | B2: Expected returns | C2: St.Deviation | D2: Min Weight | E2: Max Weight | F2: weight | J2: MAIT | K2: SAEM | L2: TISC
A3: MAIT | B3: 0.0014020999 | C3: 0.028322985 | D3: 0.02 | E3: 0.4 | F3: 0.4 | I3: MAIT | J3: =VARP([2]Sheet1!$A$3:$A$986) -> 0.00080137626 | K3: 0.0004149776 | L3: 0.00021838683
A4: SAEM | B4: 0.0034570086 | C4: 0.031763023 | D4: 0.02 | E4: 0.4 | F4: 0.4 | I4: SAEM | J4: 0.0004149776 | K4: =VARP([2]Sheet1!$B$3:$B$986) -> 0.0010078643 | L4: 0.00028912718
A5: TISC | B5: 0.0020401401 | C5: 0.022988461 | D5: 0.02 | E5: 0.4 | F5: 0.2 | I5: TISC | J5: 0.00021838683 | K5: 0.00028912718 | L5: =VARP([2]Sheet1!$C$3:$C$986) -> 0.00052793226
A20: Risk Free rate | B20: =C20/365 -> 0.00019178082 | C20: 0.07
A21: Sharp Ratio | B21: =B22-B20/B23 -> -0.0060215932
A22: Expected returns | B22: =SUMPRODUCT(B3:B5,F3:F5) -> 0.0023516714 | C22: =B22*252 -> 0.5926212
A23: Risk (Portfolio) | B23: {=SQRT(MMULT(TRANSPOSE(F3:F5),MMULT(J3:L5,F3:F5)))} -> 0.022903949
A24: Total | B24: =SUM(F3:F17) -> 1

Sheet METALS MAX PROFIT
A2: ASSETS | B2: Expected returns | C2: St.Deviation | D2: Min Weight | E2: Max Weight | F2: weight | J2: MAIT | K2: SAEM | L2: TISC
A3: MAIT | B3: 0.0014020999 | C3: 0.028322985 | D3: 0.02 | E3: 0.4 | F3: 0.2 | I3: MAIT | J3: =VARP([2]Sheet1!$A$3:$A$986) -> 0.00080137626 | K3: 0.0004149776 | L3: 0.00021838683
A4: SAEM | B4: 0.0034570086 | C4: 0.031763023 | D4: 0.02 | E4: 0.4 | F4: 0.4 | I4: SAEM | J4: 0.0004149776 | K4: =VARP([2]Sheet1!$B$3:$B$986) -> 0.0010078643 | L4: 0.00028912718
A5: TISC | B5: 0.0020401401 | C5: 0.022988461 | D5: 0.02 | E5: 0.4 | F5: 0.4 | I5: TISC | J5: 0.00021838683 | K5: 0.00028912718 | L5: =VARP([2]Sheet1!$C$3:$C$986) -> 0.00052793226
A20: Risk Free rate | B20: =C20/365 -> 0.00019178082 | C20: 0.07
A21: Sharp Ratio | B21: =B22-B20/B23 -> -0.0063515025
A22: Expected returns | B22: =SUMPRODUCT(B3:B5,F3:F5) -> 0.0024792795 | C22: =B22*252 -> 0.62477842
A23: Risk (Portfolio) | B23: {=SQRT(MMULT(TRANSPOSE(F3:F5),MMULT(J3:L5,F3:F5)))} -> 0.021717309
A24: Total | B24: =SUM(F3:F17) -> 1

Sheet BENCHMARKING
B3: Max Returns | E3: Max Sharpe | H3: NIFTY 50 | K3: Equal Weight
B4: Expected returns | C4: 0.0026340331 | E4: Expected returns | F4: 0.0023177535 | H4: Expected returns | I4: 0.001028328 | K4: Expected returns | L4: 0.001935029
B5: Risk (Portfolio) | C5: 0.016272745 | E5: Risk (Portfolio) | F5: 0.01986736 | H5: Risk (Portfolio) | I5: 0.010394669 | K5: Risk (Portfolio) | L5: 0.013643028
A8: TELECOM | B8: Expected returns | C8: 0.0022657877 | E8: Expected returns | F8: 0.0022061069
B9: Risk (Portfolio) | C9: 0.022692769 | E9: Risk (Portfolio) | F9: 0.026189343
A11: Oil and gas | B11: Expected returns | C11: 0.00075886926 | E11: Expected returns | F11: 0.0021749848
B12: Risk (Portfolio) | C12: 0.020893729 | E12: Risk (Portfolio) | F12: 0.023186975
A14: Consumer Electronics | B14: Expected returns | C14: 0.00075886926 | E14: Expected returns | F14: 0.00066368719
B15: Risk (Portfolio) | C15: 0.013161374 | E15: Risk (Portfolio) | F15: 0.013431822
A17: Metals | B17: Expected returns | C17: 0.0024792795 | E17: Expected returns | F17: 0.0023516714
B18: Risk (Portfolio) | C18: 0.021717309 | E18: Risk (Portfolio) | F18: 0.022903949
A20: Constructions | B20: Expected returns | C20: 0.0025423834 | E20: Expected returns | F20: 0.0025423834
B21: Risk (Portfolio) | C21: 0.021691289 | E21: Risk (Portfolio) | F21: 0.021691289

Sheet Nifty Data
A1: NIFTY Returns (Same period)
A2: -0.040004652 | I2: NIFTY Returns (Same period)
A3: -0.020596574
A4: 0.087632054 | I4: Mean | J4: 0.001028328
A5: -0.0049418803 | I5: Standard Error | J5: 0.00033103369
A6: 0.041508787 | I6: Median | J6: 0.0014399561
A7: -0.012955586 | I7: Mode | J7: #N/A
A8: -0.0076218749 | I8: Standard Deviation | J8: 0.010394669
A9: 0.007562771 | I9: Sample Variance | J9: 0.00010804914
A10: 0.030463259 | I10: Kurtosis | J10: 7.238983
A11: -0.00052877222 | I11: Skewness | J11: 0.12932468
A12: -0.030274729 | I12: Range | J12: 0.14507686
A13: 0.022919462 | I13: Minimum | J13: -0.057444802
A14: 0.013779892 | I14: Maximum | J14: 0.087632054
A15: -0.017124942 | I15: Sum | J15: 1.0139314
A16: 0.013971424
A17: 0.010622367
A18: 0.018383098
A19: 0.03208822
A20: -0.057444802
A21: -0.0094582235
A22: 0.0070935083
A23: -0.0077500566
A24: 0.0057016757
A25: -0.0013295141
A26: -0.0046162005
A27: 0.020333712
... A987: 0.0060509968

Sheet Max Sharpe
A2: ASSETS | B2: Expected returns | C2: St.Deviation | D2: Min Weight | E2: Max Weight | F2: weight | I2: TATA COMMUNICATION | J2: NELCO | K2: INDUSTOWER | L2: ANTELOPUS | M2: ONGC | N2: HINDOILEXP | O2: TTKPRESTIG | P2: VOLTAS | Q2: WHR | R2: MAIT | S2: SAEM | T2: TISC | U2: WELENT | V2: INDIANHUME | W2: JINDRILL
A3: TATA COMMUNICATION | B3: 0.0024448301 | C3: 0.02407353 | D3: 0.02 | E3: 0.2 | F3: 0.02 | I3: =VARP('RAW DATA'!$C$3:$C$986) -> 0.00057894588 | J3: 0.00016516084 | K3: 0.00016516084 | L3: 6.033018e-05 | M3: 4.9171217e-05 | N3: 9.7821865e-05 | O3: 5.3888251e-05 | P3: 7.646613e-05 | Q3: 4.8610567e-05 | R3: 8.7099744e-05 | S3: 9.5884466e-05 | T3: 0.00011382922 | U3: 0.00011734188 | V3: 0.00012768927 | W3: 3.8766489e-05
A4: NELCO | B4: 0.0021464261 | C4: 0.030885191 | D4: 0.02 | E4: 0.2 | F4: 0.2 | I4: 0.00016516084 | J4: =VARP('RAW DATA'!$D$3:$D$986) -> 0.00095292564 | K4: =VARP('RAW DATA'!$D$3:$D$986) -> 0.00095292564 | L4: 0.00095292564 | M4: 0.00015783596 | N4: 0.00010986807 | O4: 0.00015178595 | P4: 9.8095571e-05 | Q4: 0.00012733342 | R4: 7.0166837e-06 | S4: 0.0001738531 | T4: 0.00017761837 | U4: 0.00015858305 | V4: 0.00022453902 | W4: 0.00018890325
A5: INDUSTOWER | B5: 0.0021464261 | C5: 0.030885191 | D5: 0.02 | E5: 0.2 | F5: 0.2 | I5: 0.00016516084 | J5: 0.00095292564 | K5: =VARP('RAW DATA'!$E$3:$E$986) -> 0.00095292564 | L5: 0.00015783596 | M5: 0.00010986807 | N5: 0.00015178595 | O5: 9.8095571e-05 | P5: 0.00012733342 | Q5: 7.0166837e-06 | R5: 0.0001738531 | S5: 0.00017761837 | T5: 0.00015858305 | U5: 0.00018440729 | V5: 0.00022453902 | W5: 0.00018890325
A6: ANTELOPUS | B6: 0.0024371922 | C6: 0.031773369 | D6: 0.02 | E6: 0.2 | F6: 0.2 | I6: 6.033018e-05 | J6: 0.00015783596 | K6: 0.00015783596 | L6: =VARP('RAW DATA'!$G$3:$G$986) -> 0.001008521 | M6: 0.00018582472 | N6: 0.00032669343 | O6: 8.5836168e-05 | P6: 9.063212e-05 | Q6: -4.4489584e-06 | R6: 0.00015184175 | S6: 0.0001638687 | T6: 0.0001647564 | U6: 0.00018009502 | V6: 0.00023004539 | W6: 0.00031196846
A7: ONGC | B7: 0.0016580697 | C7: 0.021902873 | D7: 0.02 | E7: 0.2 | F7: 0.02 | I7: 4.9171217e-05 | J7: 0.00010986807 | K7: 0.00010986807 | L7: 0.00018582472 | M7: =VARP('RAW DATA'!$H$3:$H$986) -> 0.00047924829 | N7: 0.00025885668 | O7: 3.8360331e-05 | P7: 5.6361061e-05 | Q7: -3.3865738e-05 | R7: 0.00013018736 | S7: 0.00018136512 | T7: 0.00016663198 | U7: 7.5373753e-05 | V7: 8.2277988e-05 | W7: 0.00016921791
A8: HINDOILEXP | B8: 0.0021712349 | C8: 0.033689403 | D8: 0.02 | E8: 0.2 | F8: 0.02 | I8: 9.7821865e-05 | J8: 0.00015178595 | K8: 0.00015178595 | L8: 0.00032669343 | M8: 0.00025885668 | N8: =VARP('RAW DATA'!$I$3:$I$986) -> 0.0011338224 | O8: 5.7626895e-05 | P8: 8.8228269e-05 | Q8: -3.260968e-05 | R8: 0.00024186144 | S8: 0.00028683705 | T8: 0.00020895332 | U8: 0.00016570475 | V8: 0.0001796993 | W8: 0.00034262221
A9: TTKPRESTIG | B9: 0.00058635972 | C9: 0.021112772 | D9: 0.02 | E9: 0.2 | F9: 0.02 | I9: 5.3888251e-05 | J9: 9.8095571e-05 | K9: 9.8095571e-05 | L9: 8.5836168e-05 | M9: 3.8360331e-05 | N9: 5.7626895e-05 | O9: =VARP('RAW DATA'!$K$3:$K$986) -> 0.00044529613 | P9: 8.1027214e-05 | Q9: -2.2564534e-06 | R9: 8.2782905e-05 | S9: 6.7750345e-05 | T9: 8.8808049e-05 | U9: 8.8092999e-05 | V9: 0.00010686065 | W9: 6.9422198e-05
A10: VOLTAS | B10: 0.0010325124 | C10: 0.018865176 | D10: 0.02 | E10: 0.2 | F10: 0.02 | I10: 7.646613e-05 | J10: 0.00012733342 | K10: 0.00012733342 | L10: 9.063212e-05 | M10: 5.6361061e-05 | N10: 8.8228269e-05 | O10: 8.1027214e-05 | P10: =VARP('RAW DATA'!$L$3:$L$986) -> 0.00035553317 | Q10: -9.6193066e-06 | R10: 8.4112128e-05 | S10: 9.1672711e-05 | T10: 0.00015743805 | U10: 0.00014422675 | V10: 0.00012794165 | W10: 7.6721487e-05
A11: WHR | B11: 0.00055660205 | C11: 0.022957518 | D11: 0.02 | E11: 0.2 | F11: 0.02 | I11: 4.8610567e-05 | J11: 7.0166837e-06 | K11: 7.0166837e-06 | L11: -4.4489584e-06 | M11: -3.3865738e-05 | N11: -3.260968e-05 | O11: -2.2564534e-06 | P11: -9.6193066e-06 | Q11: =VARP('RAW DATA'!$M$3:$M$986) -> 0.00052651201 | R11: 2.4947342e-05 | S11: -7.3582395e-06 | T11: -4.5296734e-06 | U11: -2.6312249e-05 | V11: 1.7128122e-05 | W11: 6.81264e-06
A12: MAIT | B12: 0.0014020999 | C12: 0.028322985 | D12: 0.02 | E12: 0.2 | F12: 0.02 | I12: 8.7099744e-05 | J12: 0.0001738531 | K12: 0.0001738531 | L12: 0.00015184175 | M12: 0.00013018736 | N12: 0.00024186144 | O12: 8.2782905e-05 | P12: 8.4112128e-05 | Q12: 2.4947342e-05 | R12: =VARP('RAW DATA'!$O$3:$O$986) -> 0.00080137626 | S12: 0.0004149776 | T12: 0.00021838683 | U12: 0.0001234894 | V12: 0.00016137007 | W12: 0.00027047275
A13: SAEM | B13: 0.0034570086 | C13: 0.031763023 | D13: 0.02 | E13: 0.2 | F13: 0.02 | I13: 9.5884466e-05 | J13: 0.00017761837 | K13: 0.00017761837 | L13: 0.0001638687 | M13: 0.00018136512 | N13: 0.00028683705 | O13: 6.7750345e-05 | P13: 9.1672711e-05 | Q13: -7.3582395e-06 | R13: 0.0004149776 | S13: =VARP('RAW DATA'!$P$3:$P$986) -> 0.0010078643 | T13: 0.00028912718 | U13: 0.00014805342 | V13: 0.00017542147 | W13: 0.00028371576
A14: TISC | B14: 0.0020401401 | C14: 0.022988461 | D14: 0.02 | E14: 0.2 | F14: 0.02 | I14: 0.00011382922 | J14: 0.00015858305 | K14: 0.00015858305 | L14: 0.0001647564 | M14: 0.00016663198 | N14: 0.00020895332 | O14: 8.8808049e-05 | P14: 0.00015743805 | Q14: -4.5296734e-06 | R14: 0.00021838683 | S14: 0.00028912718 | T14: =VARP('RAW DATA'!$Q$3:$Q$986) -> 0.00052793226 | U14: 0.00017216876 | V14: 0.00016815136 | W14: 0.00015010744
A15: WELENT | B15: 0.002491596 | C15: 0.029235778 | D15: 0.02 | E15: 0.2 | F15: 0.02 | I15: 0.00011734188 | J15: 0.00018440729 | K15: 0.00018440729 | L15: 0.00018009502 | M15: 7.5373753e-05 | N15: 0.00016570475 | O15: 8.8092999e-05 | P15: 0.00014422675 | Q15: -2.6312249e-05 | R15: 0.0001234894 | S15: 0.00014805342 | T15: 0.00017216876 | U15: =VARP('RAW DATA'!$S$3:$S$986) -> 0.00085386206 | V15: 0.00025073953 | W15: 0.00016396351
A16: INDIANHUME | B16: 0.001152138 | C16: 0.028090107 | D16: 0.02 | E16: 0.2 | F16: 0.02 | I16: 0.00012768927 | J16: 0.00022453902 | K16: 0.00022453902 | L16: 0.00023004539 | M16: 8.2277988e-05 | N16: 0.0001796993 | O16: 0.00010686065 | P16: 0.00012794165 | Q16: 1.7128122e-05 | R16: 0.00016137007 | S16: 0.00017542147 | T16: 0.00016815136 | U16: 0.00025073953 | V16: =VARP('RAW DATA'!$T$3:$T$986) -> 0.00078825221 | W16: 0.00019236754
A17: JINDRILL | B17: 0.0032882935 | C17: 0.033464593 | D17: 0.02 | E17: 0.2 | F17: 0.18 | I17: 3.8766489e-05 | J17: 0.00018890325 | K17: 0.00018890325 | L17: 0.00031196846 | M17: 0.00016921791 | N17: 0.00034262221 | O17: 6.9422198e-05 | P17: 7.6721487e-05 | Q17: 6.81264e-06 | R17: 0.00027047275 | S17: 0.00028371576 | T17: 0.00015010744 | U17: 0.00016396351 | V17: 0.00019236754 | W17: =VARP('RAW DATA'!$U$3:$U$986) -> 0.0011187409
A20: Risk Free rate | B20: =C20/365 -> 0.00019178082 | C20: 0.07
A21: Sharp Ratio | B21: =B22-B20/B23 -> -0.0073353065
A22: Expected returns | B22: =SUMPRODUCT(B3:B17,F3:F17) -> 0.0023177535 | C22: =B22*252 -> 0.58407389
A23: Risk (Portfolio) | B23: {=SQRT(MMULT(TRANSPOSE(F3:F17),MMULT(I3:W17,F3:F17)))} -> 0.01986736
A24: Total | B24: =SUM(F3:F17) -> 1

Sheet Equal weight
A2: ASSETS | B2: Expected returns | C2: St.Deviation | D2: Min Weight | E2: Max Weight | F2: weight | I2: TATA COMMUNICATION | J2: NELCO | K2: INDUSTOWER | L2: ANTELOPUS | M2: ONGC | N2: HINDOILEXP | O2: TTKPRESTIG | P2: VOLTAS | Q2: WHR | R2: MAIT | S2: SAEM | T2: TISC | U2: WELENT | V2: INDIANHUME | W2: JINDRILL
A3: TATA COMMUNICATION | B3: 0.0024448301 | C3: 0.02407353 | D3: 0.02 | E3: 0.2 | F3: 0.0667 | I3: =VARP('RAW DATA'!$C$3:$C$986) -> 0.00057894588 | J3: 0.00016516084 | K3: 0.00016516084 | L3: 6.033018e-05 | M3: 4.9171217e-05 | N3: 9.7821865e-05 | O3: 5.3888251e-05 | P3: 7.646613e-05 | Q3: 4.8610567e-05 | R3: 8.7099744e-05 | S3: 9.5884466e-05 | T3: 0.00011382922 | U3: 0.00011734188 | V3: 0.00012768927 | W3: 3.8766489e-05
A4: NELCO | B4: 0.0021464261 | C4: 0.030885191 | D4: 0.02 | E4: 0.2 | F4: 0.0667 | I4: 0.00016516084 | J4: =VARP('RAW DATA'!$D$3:$D$986) -> 0.00095292564 | K4: =VARP('RAW DATA'!$D$3:$D$986) -> 0.00095292564 | L4: 0.00095292564 | M4: 0.00015783596 | N4: 0.00010986807 | O4: 0.00015178595 | P4: 9.8095571e-05 | Q4: 0.00012733342 | R4: 7.0166837e-06 | S4: 0.0001738531 | T4: 0.00017761837 | U4: 0.00015858305 | V4: 0.00022453902 | W4: 0.00018890325
A5: INDUSTOWER | B5: 0.0021464261 | C5: 0.030885191 | D5: 0.02 | E5: 0.2 | F5: 0.0667 | I5: 0.00016516084 | J5: 0.00095292564 | K5: =VARP('RAW DATA'!$E$3:$E$986) -> 0.00095292564 | L5: 0.00015783596 | M5: 0.00010986807 | N5: 0.00015178595 | O5: 9.8095571e-05 | P5: 0.00012733342 | Q5: 7.0166837e-06 | R5: 0.0001738531 | S5: 0.00017761837 | T5: 0.00015858305 | U5: 0.00018440729 | V5: 0.00022453902 | W5: 0.00018890325
A6: ANTELOPUS | B6: 0.0024371922 | C6: 0.031773369 | D6: 0.02 | E6: 0.2 | F6: 0.0667 | I6: 6.033018e-05 | J6: 0.00015783596 | K6: 0.00015783596 | L6: =VARP('RAW DATA'!$G$3:$G$986) -> 0.001008521 | M6: 0.00018582472 | N6: 0.00032669343 | O6: 8.5836168e-05 | P6: 9.063212e-05 | Q6: -4.4489584e-06 | R6: 0.00015184175 | S6: 0.0001638687 | T6: 0.0001647564 | U6: 0.00018009502 | V6: 0.00023004539 | W6: 0.00031196846
A7: ONGC | B7: 0.0016580697 | C7: 0.021902873 | D7: 0.02 | E7: 0.2 | F7: 0.0667 | I7: 4.9171217e-05 | J7: 0.00010986807 | K7: 0.00010986807 | L7: 0.00018582472 | M7: =VARP('RAW DATA'!$H$3:$H$986) -> 0.00047924829 | N7: 0.00025885668 | O7: 3.8360331e-05 | P7: 5.6361061e-05 | Q7: -3.3865738e-05 | R7: 0.00013018736 | S7: 0.00018136512 | T7: 0.00016663198 | U7: 7.5373753e-05 | V7: 8.2277988e-05 | W7: 0.00016921791
A8: HINDOILEXP | B8: 0.0021712349 | C8: 0.033689403 | D8: 0.02 | E8: 0.2 | F8: 0.0667 | I8: 9.7821865e-05 | J8: 0.00015178595 | K8: 0.00015178595 | L8: 0.00032669343 | M8: 0.00025885668 | N8: =VARP('RAW DATA'!$I$3:$I$986) -> 0.0011338224 | O8: 5.7626895e-05 | P8: 8.8228269e-05 | Q8: -3.260968e-05 | R8: 0.00024186144 | S8: 0.00028683705 | T8: 0.00020895332 | U8: 0.00016570475 | V8: 0.0001796993 | W8: 0.00034262221
A9: TTKPRESTIG | B9: 0.00058635972 | C9: 0.021112772 | D9: 0.02 | E9: 0.2 | F9: 0.0667 | I9: 5.3888251e-05 | J9: 9.8095571e-05 | K9: 9.8095571e-05 | L9: 8.5836168e-05 | M9: 3.8360331e-05 | N9: 5.7626895e-05 | O9: =VARP('RAW DATA'!$K$3:$K$986) -> 0.00044529613 | P9: 8.1027214e-05 | Q9: -2.2564534e-06 | R9: 8.2782905e-05 | S9: 6.7750345e-05 | T9: 8.8808049e-05 | U9: 8.8092999e-05 | V9: 0.00010686065 | W9: 6.9422198e-05
A10: VOLTAS | B10: 0.0010325124 | C10: 0.018865176 | D10: 0.02 | E10: 0.2 | F10: 0.0667 | I10: 7.646613e-05 | J10: 0.00012733342 | K10: 0.00012733342 | L10: 9.063212e-05 | M10: 5.6361061e-05 | N10: 8.8228269e-05 | O10: 8.1027214e-05 | P10: =VARP('RAW DATA'!$L$3:$L$986) -> 0.00035553317 | Q10: -9.6193066e-06 | R10: 8.4112128e-05 | S10: 9.1672711e-05 | T10: 0.00015743805 | U10: 0.00014422675 | V10: 0.00012794165 | W10: 7.6721487e-05
A11: WHR | B11: 0.00055660205 | C11: 0.022957518 | D11: 0.02 | E11: 0.2 | F11: 0.0667 | I11: 4.8610567e-05 | J11: 7.0166837e-06 | K11: 7.0166837e-06 | L11: -4.4489584e-06 | M11: -3.3865738e-05 | N11: -3.260968e-05 | O11: -2.2564534e-06 | P11: -9.6193066e-06 | Q11: =VARP('RAW DATA'!$M$3:$M$986) -> 0.00052651201 | R11: 2.4947342e-05 | S11: -7.3582395e-06 | T11: -4.5296734e-06 | U11: -2.6312249e-05 | V11: 1.7128122e-05 | W11: 6.81264e-06
